[2024-03-30T00:45:11.362+0000] {taskinstance.py:1979} INFO - Dependencies all met for dep_context=non-requeueable deps ti=<TaskInstance: migrate_student_data_to_snowflake.load_data_to_snowflake manual__2024-03-30T00:39:55.567844+00:00 [queued]>
[2024-03-30T00:45:11.372+0000] {taskinstance.py:1979} INFO - Dependencies all met for dep_context=requeueable deps ti=<TaskInstance: migrate_student_data_to_snowflake.load_data_to_snowflake manual__2024-03-30T00:39:55.567844+00:00 [queued]>
[2024-03-30T00:45:11.373+0000] {taskinstance.py:2193} INFO - Starting attempt 2 of 2
[2024-03-30T00:45:11.392+0000] {taskinstance.py:2217} INFO - Executing <Task(PythonOperator): load_data_to_snowflake> on 2024-03-30 00:39:55.567844+00:00
[2024-03-30T00:45:11.398+0000] {standard_task_runner.py:60} INFO - Started process 197 to run task
[2024-03-30T00:45:11.402+0000] {standard_task_runner.py:87} INFO - Running: ['***', 'tasks', 'run', 'migrate_student_data_to_snowflake', 'load_data_to_snowflake', 'manual__2024-03-30T00:39:55.567844+00:00', '--job-id', '104', '--raw', '--subdir', 'DAGS_FOLDER/student_data_migration.py', '--cfg-path', '/tmp/tmpmz68ogvi']
[2024-03-30T00:45:11.404+0000] {standard_task_runner.py:88} INFO - Job 104: Subtask load_data_to_snowflake
[2024-03-30T00:45:11.459+0000] {task_command.py:423} INFO - Running <TaskInstance: migrate_student_data_to_snowflake.load_data_to_snowflake manual__2024-03-30T00:39:55.567844+00:00 [running]> on host 2417d3f97037
[2024-03-30T00:45:11.599+0000] {taskinstance.py:2513} INFO - Exporting env vars: AIRFLOW_CTX_DAG_OWNER='***' AIRFLOW_CTX_DAG_ID='migrate_student_data_to_snowflake' AIRFLOW_CTX_TASK_ID='load_data_to_snowflake' AIRFLOW_CTX_EXECUTION_DATE='2024-03-30T00:39:55.567844+00:00' AIRFLOW_CTX_TRY_NUMBER='2' AIRFLOW_CTX_DAG_RUN_ID='manual__2024-03-30T00:39:55.567844+00:00'
[2024-03-30T00:45:11.600+0000] {connection.py:386} INFO - Snowflake Connector for Python Version: 3.7.1, Python Version: 3.8.19, Platform: Linux-5.15.146.1-microsoft-standard-WSL2-x86_64-with-glibc2.34
[2024-03-30T00:45:11.601+0000] {connection.py:1211} INFO - This connection is in OCSP Fail Open Mode. TLS Certificates would be checked for validity and revocation status. Any other Certificate Revocation related exceptions or OCSP Responder failures would be disregarded in favor of connectivity.
[2024-03-30T00:45:12.554+0000] {connection.py:547} WARNING - Certificate did not match expected hostname: xzazqxs.os03767.snowflakecomputing.com. Certificate: {'subject': ((('commonName', '*.prod3.us-west-2.snowflakecomputing.com'),),), 'subjectAltName': [('DNS', '*.prod3.us-west-2.snowflakecomputing.com'), ('DNS', '*.us-west-2.snowflakecomputing.com'), ('DNS', '*.global.snowflakecomputing.com'), ('DNS', '*.snowflakecomputing.com'), ('DNS', '*.prod3.us-west-2.aws.snowflakecomputing.com')]}
[2024-03-30T00:45:12.556+0000] {connectionpool.py:824} WARNING - Retrying (Retry(total=0, connect=None, read=None, redirect=None, status=None)) after connection broken by 'SSLError(CertificateError("hostname 'xzazqxs.os03767.snowflakecomputing.com' doesn't match either of '*.prod3.us-west-2.snowflakecomputing.com', '*.us-west-2.snowflakecomputing.com', '*.global.snowflakecomputing.com', '*.snowflakecomputing.com', '*.prod3.us-west-2.aws.snowflakecomputing.com'"))': /session/v1/login-request?request_id=1816d49c-8136-4cb1-af10-83bacfae977d&request_guid=82e910cd-5a5e-492c-a4a6-2cd12e97be2d
[2024-03-30T00:45:13.212+0000] {connection.py:547} WARNING - Certificate did not match expected hostname: xzazqxs.os03767.snowflakecomputing.com. Certificate: {'subject': ((('commonName', '*.prod3.us-west-2.snowflakecomputing.com'),),), 'subjectAltName': [('DNS', '*.prod3.us-west-2.snowflakecomputing.com'), ('DNS', '*.us-west-2.snowflakecomputing.com'), ('DNS', '*.global.snowflakecomputing.com'), ('DNS', '*.snowflakecomputing.com'), ('DNS', '*.prod3.us-west-2.aws.snowflakecomputing.com')]}
[2024-03-30T00:45:13.217+0000] {network.py:1029} ERROR - Failed to get the response. Hanging? method: post, url: https://XZAZQXS.OS03767.snowflakecomputing.com:443/session/v1/login-request?request_id=1816d49c-8136-4cb1-af10-83bacfae977d&request_guid=82e910cd-5a5e-492c-a4a6-2cd12e97be2d, headers:{'Content-Type': 'application/json', 'accept': 'application/snowflake', 'User-Agent': 'PythonConnector/3.7.1 (Linux-5.15.146.1-microsoft-standard-WSL2-x86_64-with-glibc2.34) CPython/3.8.19', 'Content-Encoding': 'gzip'}, data: {"data": {"CLIENT_APP_ID": "PythonConnector", "CLIENT_APP_VERSION": "3.7.1", "SVN_REVISION": null, "ACCOUNT_NAME": "XZAZQXS", "LOGIN_NAME": "THAISCVAZ", "CLIENT_ENVIRONMENT": {"APPLICATION": "PythonConnector", "OS": "Linux", "OS_VERSION": "Linux-5.15.146.1-microsoft-standard-WSL2-x86_64-with-glibc2.34", "PYTHON_VERSION": "3.8.19", "PYTHON_RUNTIME": "CPython", "PYTHON_COMPILER": "GCC 12.2.0", "OCSP_MODE": "FAIL_OPEN", "TRACING": 20, "LOGIN_TIMEOUT": null, "NETWORK_TIMEOUT": null, "SOCKET_TIMEOUT": null}, "PASSWORD": "**** "SESSION_PARAMETERS": {"CLIENT_PREFETCH_THREADS": 4}}}
[2024-03-30T00:45:14.894+0000] {connection.py:547} WARNING - Certificate did not match expected hostname: xzazqxs.os03767.snowflakecomputing.com. Certificate: {'subject': ((('commonName', '*.prod3.us-west-2.snowflakecomputing.com'),),), 'subjectAltName': [('DNS', '*.prod3.us-west-2.snowflakecomputing.com'), ('DNS', '*.us-west-2.snowflakecomputing.com'), ('DNS', '*.global.snowflakecomputing.com'), ('DNS', '*.snowflakecomputing.com'), ('DNS', '*.prod3.us-west-2.aws.snowflakecomputing.com')]}
[2024-03-30T00:45:14.896+0000] {connectionpool.py:824} WARNING - Retrying (Retry(total=0, connect=None, read=None, redirect=None, status=None)) after connection broken by 'SSLError(CertificateError("hostname 'xzazqxs.os03767.snowflakecomputing.com' doesn't match either of '*.prod3.us-west-2.snowflakecomputing.com', '*.us-west-2.snowflakecomputing.com', '*.global.snowflakecomputing.com', '*.snowflakecomputing.com', '*.prod3.us-west-2.aws.snowflakecomputing.com'"))': /session/v1/login-request?request_id=09445650-20a1-4a14-b6a8-79d1b868b66d&request_guid=0b02a0fe-98d1-4331-b311-17d9c9e8e34c
[2024-03-30T00:45:15.585+0000] {connection.py:547} WARNING - Certificate did not match expected hostname: xzazqxs.os03767.snowflakecomputing.com. Certificate: {'subject': ((('commonName', '*.prod3.us-west-2.snowflakecomputing.com'),),), 'subjectAltName': [('DNS', '*.prod3.us-west-2.snowflakecomputing.com'), ('DNS', '*.us-west-2.snowflakecomputing.com'), ('DNS', '*.global.snowflakecomputing.com'), ('DNS', '*.snowflakecomputing.com'), ('DNS', '*.prod3.us-west-2.aws.snowflakecomputing.com')]}
[2024-03-30T00:45:15.588+0000] {network.py:1029} ERROR - Failed to get the response. Hanging? method: post, url: https://XZAZQXS.OS03767.snowflakecomputing.com:443/session/v1/login-request?request_id=09445650-20a1-4a14-b6a8-79d1b868b66d&request_guid=0b02a0fe-98d1-4331-b311-17d9c9e8e34c, headers:{'Content-Type': 'application/json', 'accept': 'application/snowflake', 'User-Agent': 'PythonConnector/3.7.1 (Linux-5.15.146.1-microsoft-standard-WSL2-x86_64-with-glibc2.34) CPython/3.8.19', 'Content-Encoding': 'gzip'}, data: {"data": {"CLIENT_APP_ID": "PythonConnector", "CLIENT_APP_VERSION": "3.7.1", "SVN_REVISION": null, "ACCOUNT_NAME": "XZAZQXS", "LOGIN_NAME": "THAISCVAZ", "CLIENT_ENVIRONMENT": {"APPLICATION": "PythonConnector", "OS": "Linux", "OS_VERSION": "Linux-5.15.146.1-microsoft-standard-WSL2-x86_64-with-glibc2.34", "PYTHON_VERSION": "3.8.19", "PYTHON_RUNTIME": "CPython", "PYTHON_COMPILER": "GCC 12.2.0", "OCSP_MODE": "FAIL_OPEN", "TRACING": 20, "LOGIN_TIMEOUT": null, "NETWORK_TIMEOUT": null, "SOCKET_TIMEOUT": null}, "PASSWORD": "**** "SESSION_PARAMETERS": {"CLIENT_PREFETCH_THREADS": 4}}}
[2024-03-30T00:45:15.593+0000] {student_data_migration.py:144} ERROR - Error loading data into Snowflake: 250001: 250001: Could not connect to Snowflake backend after 2 attempt(s).Aborting
[2024-03-30T00:45:15.594+0000] {taskinstance.py:2731} ERROR - Task failed with exception
Traceback (most recent call last):
  File "/home/airflow/.local/lib/python3.8/site-packages/snowflake/connector/connection.py", line 1345, in _authenticate
    auth.authenticate(
  File "/home/airflow/.local/lib/python3.8/site-packages/snowflake/connector/auth/_auth.py", line 250, in authenticate
    ret = self._rest._post_request(
  File "/home/airflow/.local/lib/python3.8/site-packages/snowflake/connector/network.py", line 734, in _post_request
    ret = self.fetch(
  File "/home/airflow/.local/lib/python3.8/site-packages/snowflake/connector/network.py", line 843, in fetch
    ret = self._request_exec_wrapper(
  File "/home/airflow/.local/lib/python3.8/site-packages/snowflake/connector/network.py", line 979, in _request_exec_wrapper
    raise e
  File "/home/airflow/.local/lib/python3.8/site-packages/snowflake/connector/network.py", line 895, in _request_exec_wrapper
    self._handle_unknown_error(method, full_url, headers, data, conn)
  File "/home/airflow/.local/lib/python3.8/site-packages/snowflake/connector/network.py", line 1034, in _handle_unknown_error
    Error.errorhandler_wrapper(
  File "/home/airflow/.local/lib/python3.8/site-packages/snowflake/connector/errors.py", line 290, in errorhandler_wrapper
    handed_over = Error.hand_to_other_handler(
  File "/home/airflow/.local/lib/python3.8/site-packages/snowflake/connector/errors.py", line 348, in hand_to_other_handler
    connection.errorhandler(connection, cursor, error_class, error_value)
  File "/home/airflow/.local/lib/python3.8/site-packages/snowflake/connector/errors.py", line 221, in default_errorhandler
    raise error_class(
snowflake.connector.errors.OperationalError: 250003: 250003: Failed to get the response. Hanging? method: post, url: https://XZAZQXS.OS03767.snowflakecomputing.com:443/session/v1/login-request?request_id=1816d49c-8136-4cb1-af10-83bacfae977d&request_guid=82e910cd-5a5e-492c-a4a6-2cd12e97be2d

The above exception was the direct cause of the following exception:

Traceback (most recent call last):
  File "/opt/airflow/dags/student_data_migration.py", line 115, in load_data_to_snowflake
    conn = snowflake.connector.connect(
  File "/home/airflow/.local/lib/python3.8/site-packages/snowflake/connector/__init__.py", line 54, in Connect
    return SnowflakeConnection(**kwargs)
  File "/home/airflow/.local/lib/python3.8/site-packages/snowflake/connector/connection.py", line 429, in __init__
    self.connect(**kwargs)
  File "/home/airflow/.local/lib/python3.8/site-packages/snowflake/connector/connection.py", line 719, in connect
    self.__open_connection()
  File "/home/airflow/.local/lib/python3.8/site-packages/snowflake/connector/connection.py", line 1045, in __open_connection
    self.authenticate_with_retry(self.auth_class)
  File "/home/airflow/.local/lib/python3.8/site-packages/snowflake/connector/connection.py", line 1317, in authenticate_with_retry
    self._authenticate(auth_instance)
  File "/home/airflow/.local/lib/python3.8/site-packages/snowflake/connector/connection.py", line 1389, in _authenticate
    raise auth_op from e
  File "/home/airflow/.local/lib/python3.8/site-packages/snowflake/connector/connection.py", line 1366, in _authenticate
    auth_instance.handle_timeout(
  File "/home/airflow/.local/lib/python3.8/site-packages/snowflake/connector/auth/by_plugin.py", line 212, in handle_timeout
    raise error
snowflake.connector.errors.OperationalError: 250001: 250001: Could not connect to Snowflake backend after 2 attempt(s).Aborting

During handling of the above exception, another exception occurred:

Traceback (most recent call last):
  File "/home/airflow/.local/lib/python3.8/site-packages/airflow/models/taskinstance.py", line 444, in _execute_task
    result = _execute_callable(context=context, **execute_callable_kwargs)
  File "/home/airflow/.local/lib/python3.8/site-packages/airflow/models/taskinstance.py", line 414, in _execute_callable
    return execute_callable(context=context, **execute_callable_kwargs)
  File "/home/airflow/.local/lib/python3.8/site-packages/airflow/operators/python.py", line 200, in execute
    return_value = self.execute_callable()
  File "/home/airflow/.local/lib/python3.8/site-packages/airflow/operators/python.py", line 217, in execute_callable
    return self.python_callable(*self.op_args, **self.op_kwargs)
  File "/opt/airflow/dags/student_data_migration.py", line 147, in load_data_to_snowflake
    cursor.close()
UnboundLocalError: local variable 'cursor' referenced before assignment
[2024-03-30T00:45:15.603+0000] {taskinstance.py:1149} INFO - Marking task as FAILED. dag_id=migrate_student_data_to_snowflake, task_id=load_data_to_snowflake, execution_date=20240330T003955, start_date=20240330T004511, end_date=20240330T004515
[2024-03-30T00:45:15.616+0000] {standard_task_runner.py:107} ERROR - Failed to execute job 104 for task load_data_to_snowflake (local variable 'cursor' referenced before assignment; 197)
[2024-03-30T00:45:15.638+0000] {local_task_job_runner.py:234} INFO - Task exited with return code 1
[2024-03-30T00:45:15.653+0000] {taskinstance.py:3312} INFO - 0 downstream tasks scheduled from follow-on schedule check
