[2024-03-30T00:45:11.364+0000] {taskinstance.py:1979} INFO - Dependencies all met for dep_context=non-requeueable deps ti=<TaskInstance: migrate_student_data_to_snowflake.load_data_to_snowflake scheduled__2024-03-29T00:00:00+00:00 [queued]>
[2024-03-30T00:45:11.374+0000] {taskinstance.py:1979} INFO - Dependencies all met for dep_context=requeueable deps ti=<TaskInstance: migrate_student_data_to_snowflake.load_data_to_snowflake scheduled__2024-03-29T00:00:00+00:00 [queued]>
[2024-03-30T00:45:11.374+0000] {taskinstance.py:2193} INFO - Starting attempt 2 of 2
[2024-03-30T00:45:11.389+0000] {taskinstance.py:2217} INFO - Executing <Task(PythonOperator): load_data_to_snowflake> on 2024-03-29 00:00:00+00:00
[2024-03-30T00:45:11.396+0000] {standard_task_runner.py:60} INFO - Started process 196 to run task
[2024-03-30T00:45:11.400+0000] {standard_task_runner.py:87} INFO - Running: ['***', 'tasks', 'run', 'migrate_student_data_to_snowflake', 'load_data_to_snowflake', 'scheduled__2024-03-29T00:00:00+00:00', '--job-id', '103', '--raw', '--subdir', 'DAGS_FOLDER/student_data_migration.py', '--cfg-path', '/tmp/tmpsjsu936m']
[2024-03-30T00:45:11.403+0000] {standard_task_runner.py:88} INFO - Job 103: Subtask load_data_to_snowflake
[2024-03-30T00:45:11.458+0000] {task_command.py:423} INFO - Running <TaskInstance: migrate_student_data_to_snowflake.load_data_to_snowflake scheduled__2024-03-29T00:00:00+00:00 [running]> on host 2417d3f97037
[2024-03-30T00:45:11.604+0000] {taskinstance.py:2513} INFO - Exporting env vars: AIRFLOW_CTX_DAG_OWNER='***' AIRFLOW_CTX_DAG_ID='migrate_student_data_to_snowflake' AIRFLOW_CTX_TASK_ID='load_data_to_snowflake' AIRFLOW_CTX_EXECUTION_DATE='2024-03-29T00:00:00+00:00' AIRFLOW_CTX_TRY_NUMBER='2' AIRFLOW_CTX_DAG_RUN_ID='scheduled__2024-03-29T00:00:00+00:00'
[2024-03-30T00:45:11.607+0000] {connection.py:386} INFO - Snowflake Connector for Python Version: 3.7.1, Python Version: 3.8.19, Platform: Linux-5.15.146.1-microsoft-standard-WSL2-x86_64-with-glibc2.34
[2024-03-30T00:45:11.608+0000] {connection.py:1211} INFO - This connection is in OCSP Fail Open Mode. TLS Certificates would be checked for validity and revocation status. Any other Certificate Revocation related exceptions or OCSP Responder failures would be disregarded in favor of connectivity.
[2024-03-30T00:45:12.551+0000] {connection.py:547} WARNING - Certificate did not match expected hostname: xzazqxs.os03767.snowflakecomputing.com. Certificate: {'subject': ((('commonName', '*.prod3.us-west-2.snowflakecomputing.com'),),), 'subjectAltName': [('DNS', '*.prod3.us-west-2.snowflakecomputing.com'), ('DNS', '*.us-west-2.snowflakecomputing.com'), ('DNS', '*.global.snowflakecomputing.com'), ('DNS', '*.snowflakecomputing.com'), ('DNS', '*.prod3.us-west-2.aws.snowflakecomputing.com')]}
[2024-03-30T00:45:12.553+0000] {connectionpool.py:824} WARNING - Retrying (Retry(total=0, connect=None, read=None, redirect=None, status=None)) after connection broken by 'SSLError(CertificateError("hostname 'xzazqxs.os03767.snowflakecomputing.com' doesn't match either of '*.prod3.us-west-2.snowflakecomputing.com', '*.us-west-2.snowflakecomputing.com', '*.global.snowflakecomputing.com', '*.snowflakecomputing.com', '*.prod3.us-west-2.aws.snowflakecomputing.com'"))': /session/v1/login-request?request_id=7a032e10-ca5e-4523-a64b-f3f49a0a038e&request_guid=4bcc7b35-da25-4046-979b-21191f4e7af9
[2024-03-30T00:45:13.213+0000] {connection.py:547} WARNING - Certificate did not match expected hostname: xzazqxs.os03767.snowflakecomputing.com. Certificate: {'subject': ((('commonName', '*.prod3.us-west-2.snowflakecomputing.com'),),), 'subjectAltName': [('DNS', '*.prod3.us-west-2.snowflakecomputing.com'), ('DNS', '*.us-west-2.snowflakecomputing.com'), ('DNS', '*.global.snowflakecomputing.com'), ('DNS', '*.snowflakecomputing.com'), ('DNS', '*.prod3.us-west-2.aws.snowflakecomputing.com')]}
[2024-03-30T00:45:13.218+0000] {network.py:1029} ERROR - Failed to get the response. Hanging? method: post, url: https://XZAZQXS.OS03767.snowflakecomputing.com:443/session/v1/login-request?request_id=7a032e10-ca5e-4523-a64b-f3f49a0a038e&request_guid=4bcc7b35-da25-4046-979b-21191f4e7af9, headers:{'Content-Type': 'application/json', 'accept': 'application/snowflake', 'User-Agent': 'PythonConnector/3.7.1 (Linux-5.15.146.1-microsoft-standard-WSL2-x86_64-with-glibc2.34) CPython/3.8.19', 'Content-Encoding': 'gzip'}, data: {"data": {"CLIENT_APP_ID": "PythonConnector", "CLIENT_APP_VERSION": "3.7.1", "SVN_REVISION": null, "ACCOUNT_NAME": "XZAZQXS", "LOGIN_NAME": "THAISCVAZ", "CLIENT_ENVIRONMENT": {"APPLICATION": "PythonConnector", "OS": "Linux", "OS_VERSION": "Linux-5.15.146.1-microsoft-standard-WSL2-x86_64-with-glibc2.34", "PYTHON_VERSION": "3.8.19", "PYTHON_RUNTIME": "CPython", "PYTHON_COMPILER": "GCC 12.2.0", "OCSP_MODE": "FAIL_OPEN", "TRACING": 20, "LOGIN_TIMEOUT": null, "NETWORK_TIMEOUT": null, "SOCKET_TIMEOUT": null}, "PASSWORD": "**** "SESSION_PARAMETERS": {"CLIENT_PREFETCH_THREADS": 4}}}
[2024-03-30T00:45:14.894+0000] {connection.py:547} WARNING - Certificate did not match expected hostname: xzazqxs.os03767.snowflakecomputing.com. Certificate: {'subject': ((('commonName', '*.prod3.us-west-2.snowflakecomputing.com'),),), 'subjectAltName': [('DNS', '*.prod3.us-west-2.snowflakecomputing.com'), ('DNS', '*.us-west-2.snowflakecomputing.com'), ('DNS', '*.global.snowflakecomputing.com'), ('DNS', '*.snowflakecomputing.com'), ('DNS', '*.prod3.us-west-2.aws.snowflakecomputing.com')]}
[2024-03-30T00:45:14.896+0000] {connectionpool.py:824} WARNING - Retrying (Retry(total=0, connect=None, read=None, redirect=None, status=None)) after connection broken by 'SSLError(CertificateError("hostname 'xzazqxs.os03767.snowflakecomputing.com' doesn't match either of '*.prod3.us-west-2.snowflakecomputing.com', '*.us-west-2.snowflakecomputing.com', '*.global.snowflakecomputing.com', '*.snowflakecomputing.com', '*.prod3.us-west-2.aws.snowflakecomputing.com'"))': /session/v1/login-request?request_id=ceb46bda-50dc-402a-ab50-7fe1d342ff74&request_guid=18d571b0-f59c-430c-8c1c-43d0850bd7df
[2024-03-30T00:45:15.582+0000] {connection.py:547} WARNING - Certificate did not match expected hostname: xzazqxs.os03767.snowflakecomputing.com. Certificate: {'subject': ((('commonName', '*.prod3.us-west-2.snowflakecomputing.com'),),), 'subjectAltName': [('DNS', '*.prod3.us-west-2.snowflakecomputing.com'), ('DNS', '*.us-west-2.snowflakecomputing.com'), ('DNS', '*.global.snowflakecomputing.com'), ('DNS', '*.snowflakecomputing.com'), ('DNS', '*.prod3.us-west-2.aws.snowflakecomputing.com')]}
[2024-03-30T00:45:15.586+0000] {network.py:1029} ERROR - Failed to get the response. Hanging? method: post, url: https://XZAZQXS.OS03767.snowflakecomputing.com:443/session/v1/login-request?request_id=ceb46bda-50dc-402a-ab50-7fe1d342ff74&request_guid=18d571b0-f59c-430c-8c1c-43d0850bd7df, headers:{'Content-Type': 'application/json', 'accept': 'application/snowflake', 'User-Agent': 'PythonConnector/3.7.1 (Linux-5.15.146.1-microsoft-standard-WSL2-x86_64-with-glibc2.34) CPython/3.8.19', 'Content-Encoding': 'gzip'}, data: {"data": {"CLIENT_APP_ID": "PythonConnector", "CLIENT_APP_VERSION": "3.7.1", "SVN_REVISION": null, "ACCOUNT_NAME": "XZAZQXS", "LOGIN_NAME": "THAISCVAZ", "CLIENT_ENVIRONMENT": {"APPLICATION": "PythonConnector", "OS": "Linux", "OS_VERSION": "Linux-5.15.146.1-microsoft-standard-WSL2-x86_64-with-glibc2.34", "PYTHON_VERSION": "3.8.19", "PYTHON_RUNTIME": "CPython", "PYTHON_COMPILER": "GCC 12.2.0", "OCSP_MODE": "FAIL_OPEN", "TRACING": 20, "LOGIN_TIMEOUT": null, "NETWORK_TIMEOUT": null, "SOCKET_TIMEOUT": null}, "PASSWORD": "**** "SESSION_PARAMETERS": {"CLIENT_PREFETCH_THREADS": 4}}}
[2024-03-30T00:45:15.592+0000] {student_data_migration.py:144} ERROR - Error loading data into Snowflake: 250001: 250001: Could not connect to Snowflake backend after 2 attempt(s).Aborting
[2024-03-30T00:45:15.593+0000] {taskinstance.py:2731} ERROR - Task failed with exception
Traceback (most recent call last):
  File "/home/airflow/.local/lib/python3.8/site-packages/snowflake/connector/connection.py", line 1345, in _authenticate
    auth.authenticate(
  File "/home/airflow/.local/lib/python3.8/site-packages/snowflake/connector/auth/_auth.py", line 250, in authenticate
    ret = self._rest._post_request(
  File "/home/airflow/.local/lib/python3.8/site-packages/snowflake/connector/network.py", line 734, in _post_request
    ret = self.fetch(
  File "/home/airflow/.local/lib/python3.8/site-packages/snowflake/connector/network.py", line 843, in fetch
    ret = self._request_exec_wrapper(
  File "/home/airflow/.local/lib/python3.8/site-packages/snowflake/connector/network.py", line 979, in _request_exec_wrapper
    raise e
  File "/home/airflow/.local/lib/python3.8/site-packages/snowflake/connector/network.py", line 895, in _request_exec_wrapper
    self._handle_unknown_error(method, full_url, headers, data, conn)
  File "/home/airflow/.local/lib/python3.8/site-packages/snowflake/connector/network.py", line 1034, in _handle_unknown_error
    Error.errorhandler_wrapper(
  File "/home/airflow/.local/lib/python3.8/site-packages/snowflake/connector/errors.py", line 290, in errorhandler_wrapper
    handed_over = Error.hand_to_other_handler(
  File "/home/airflow/.local/lib/python3.8/site-packages/snowflake/connector/errors.py", line 348, in hand_to_other_handler
    connection.errorhandler(connection, cursor, error_class, error_value)
  File "/home/airflow/.local/lib/python3.8/site-packages/snowflake/connector/errors.py", line 221, in default_errorhandler
    raise error_class(
snowflake.connector.errors.OperationalError: 250003: 250003: Failed to get the response. Hanging? method: post, url: https://XZAZQXS.OS03767.snowflakecomputing.com:443/session/v1/login-request?request_id=7a032e10-ca5e-4523-a64b-f3f49a0a038e&request_guid=4bcc7b35-da25-4046-979b-21191f4e7af9

The above exception was the direct cause of the following exception:

Traceback (most recent call last):
  File "/opt/airflow/dags/student_data_migration.py", line 115, in load_data_to_snowflake
    conn = snowflake.connector.connect(
  File "/home/airflow/.local/lib/python3.8/site-packages/snowflake/connector/__init__.py", line 54, in Connect
    return SnowflakeConnection(**kwargs)
  File "/home/airflow/.local/lib/python3.8/site-packages/snowflake/connector/connection.py", line 429, in __init__
    self.connect(**kwargs)
  File "/home/airflow/.local/lib/python3.8/site-packages/snowflake/connector/connection.py", line 719, in connect
    self.__open_connection()
  File "/home/airflow/.local/lib/python3.8/site-packages/snowflake/connector/connection.py", line 1045, in __open_connection
    self.authenticate_with_retry(self.auth_class)
  File "/home/airflow/.local/lib/python3.8/site-packages/snowflake/connector/connection.py", line 1317, in authenticate_with_retry
    self._authenticate(auth_instance)
  File "/home/airflow/.local/lib/python3.8/site-packages/snowflake/connector/connection.py", line 1389, in _authenticate
    raise auth_op from e
  File "/home/airflow/.local/lib/python3.8/site-packages/snowflake/connector/connection.py", line 1366, in _authenticate
    auth_instance.handle_timeout(
  File "/home/airflow/.local/lib/python3.8/site-packages/snowflake/connector/auth/by_plugin.py", line 212, in handle_timeout
    raise error
snowflake.connector.errors.OperationalError: 250001: 250001: Could not connect to Snowflake backend after 2 attempt(s).Aborting

During handling of the above exception, another exception occurred:

Traceback (most recent call last):
  File "/home/airflow/.local/lib/python3.8/site-packages/airflow/models/taskinstance.py", line 444, in _execute_task
    result = _execute_callable(context=context, **execute_callable_kwargs)
  File "/home/airflow/.local/lib/python3.8/site-packages/airflow/models/taskinstance.py", line 414, in _execute_callable
    return execute_callable(context=context, **execute_callable_kwargs)
  File "/home/airflow/.local/lib/python3.8/site-packages/airflow/operators/python.py", line 200, in execute
    return_value = self.execute_callable()
  File "/home/airflow/.local/lib/python3.8/site-packages/airflow/operators/python.py", line 217, in execute_callable
    return self.python_callable(*self.op_args, **self.op_kwargs)
  File "/opt/airflow/dags/student_data_migration.py", line 147, in load_data_to_snowflake
    cursor.close()
UnboundLocalError: local variable 'cursor' referenced before assignment
[2024-03-30T00:45:15.602+0000] {taskinstance.py:1149} INFO - Marking task as FAILED. dag_id=migrate_student_data_to_snowflake, task_id=load_data_to_snowflake, execution_date=20240329T000000, start_date=20240330T004511, end_date=20240330T004515
[2024-03-30T00:45:15.614+0000] {standard_task_runner.py:107} ERROR - Failed to execute job 103 for task load_data_to_snowflake (local variable 'cursor' referenced before assignment; 196)
[2024-03-30T00:45:15.636+0000] {local_task_job_runner.py:234} INFO - Task exited with return code 1
[2024-03-30T00:45:15.653+0000] {taskinstance.py:3312} INFO - 0 downstream tasks scheduled from follow-on schedule check
[2024-03-30T01:56:14.981+0000] {taskinstance.py:1979} INFO - Dependencies all met for dep_context=non-requeueable deps ti=<TaskInstance: migrate_student_data_to_snowflake.load_data_to_snowflake scheduled__2024-03-29T00:00:00+00:00 [queued]>
[2024-03-30T01:56:14.996+0000] {taskinstance.py:1979} INFO - Dependencies all met for dep_context=requeueable deps ti=<TaskInstance: migrate_student_data_to_snowflake.load_data_to_snowflake scheduled__2024-03-29T00:00:00+00:00 [queued]>
[2024-03-30T01:56:14.996+0000] {taskinstance.py:2193} INFO - Starting attempt 2 of 2
[2024-03-30T01:56:15.006+0000] {taskinstance.py:2217} INFO - Executing <Task(PythonOperator): load_data_to_snowflake> on 2024-03-29 00:00:00+00:00
[2024-03-30T01:56:15.011+0000] {standard_task_runner.py:60} INFO - Started process 206 to run task
[2024-03-30T01:56:15.014+0000] {standard_task_runner.py:87} INFO - Running: ['***', 'tasks', 'run', 'migrate_student_data_to_snowflake', 'load_data_to_snowflake', 'scheduled__2024-03-29T00:00:00+00:00', '--job-id', '144', '--raw', '--subdir', 'DAGS_FOLDER/student_data_migration.py', '--cfg-path', '/tmp/tmpuxe5ra10']
[2024-03-30T01:56:15.017+0000] {standard_task_runner.py:88} INFO - Job 144: Subtask load_data_to_snowflake
[2024-03-30T01:56:15.057+0000] {task_command.py:423} INFO - Running <TaskInstance: migrate_student_data_to_snowflake.load_data_to_snowflake scheduled__2024-03-29T00:00:00+00:00 [running]> on host 4eb3fd2c57a4
[2024-03-30T01:56:15.186+0000] {taskinstance.py:2513} INFO - Exporting env vars: AIRFLOW_CTX_DAG_OWNER='***' AIRFLOW_CTX_DAG_ID='migrate_student_data_to_snowflake' AIRFLOW_CTX_TASK_ID='load_data_to_snowflake' AIRFLOW_CTX_EXECUTION_DATE='2024-03-29T00:00:00+00:00' AIRFLOW_CTX_TRY_NUMBER='2' AIRFLOW_CTX_DAG_RUN_ID='scheduled__2024-03-29T00:00:00+00:00'
[2024-03-30T01:56:15.187+0000] {connection.py:386} INFO - Snowflake Connector for Python Version: 3.7.1, Python Version: 3.8.19, Platform: Linux-5.15.146.1-microsoft-standard-WSL2-x86_64-with-glibc2.34
[2024-03-30T01:56:15.188+0000] {connection.py:1211} INFO - This connection is in OCSP Fail Open Mode. TLS Certificates would be checked for validity and revocation status. Any other Certificate Revocation related exceptions or OCSP Responder failures would be disregarded in favor of connectivity.
[2024-03-30T01:56:15.940+0000] {cursor.py:1032} INFO - query: [CREATE OR REPLACE TABLE FINAL_MERGED ( student_id VARCHAR, name VARCHAR, grades ...]
[2024-03-30T01:56:16.106+0000] {cursor.py:1045} INFO - query execution done
[2024-03-30T01:56:16.112+0000] {student_data_migration.py:139} ERROR - Error loading data into Snowflake: 090105 (22000): 01b352ef-0000-3e0f-0000-0000499135e1: Cannot perform CREATE TABLE. This session does not have a current database. Call 'USE DATABASE', or use a qualified name.
[2024-03-30T01:56:16.112+0000] {connection.py:734} INFO - closed
[2024-03-30T01:56:16.153+0000] {connection.py:740} INFO - No async queries seem to be running, deleting session
[2024-03-30T01:56:16.202+0000] {taskinstance.py:2731} ERROR - Task failed with exception
Traceback (most recent call last):
  File "/home/airflow/.local/lib/python3.8/site-packages/airflow/models/taskinstance.py", line 444, in _execute_task
    result = _execute_callable(context=context, **execute_callable_kwargs)
  File "/home/airflow/.local/lib/python3.8/site-packages/airflow/models/taskinstance.py", line 414, in _execute_callable
    return execute_callable(context=context, **execute_callable_kwargs)
  File "/home/airflow/.local/lib/python3.8/site-packages/airflow/operators/python.py", line 200, in execute
    return_value = self.execute_callable()
  File "/home/airflow/.local/lib/python3.8/site-packages/airflow/operators/python.py", line 217, in execute_callable
    return self.python_callable(*self.op_args, **self.op_kwargs)
  File "/opt/airflow/dags/student_data_migration.py", line 122, in load_data_to_snowflake
    cursor.execute("""
  File "/home/airflow/.local/lib/python3.8/site-packages/snowflake/connector/cursor.py", line 1136, in execute
    Error.errorhandler_wrapper(self.connection, self, error_class, errvalue)
  File "/home/airflow/.local/lib/python3.8/site-packages/snowflake/connector/errors.py", line 290, in errorhandler_wrapper
    handed_over = Error.hand_to_other_handler(
  File "/home/airflow/.local/lib/python3.8/site-packages/snowflake/connector/errors.py", line 345, in hand_to_other_handler
    cursor.errorhandler(connection, cursor, error_class, error_value)
  File "/home/airflow/.local/lib/python3.8/site-packages/snowflake/connector/errors.py", line 221, in default_errorhandler
    raise error_class(
snowflake.connector.errors.ProgrammingError: 090105 (22000): 01b352ef-0000-3e0f-0000-0000499135e1: Cannot perform CREATE TABLE. This session does not have a current database. Call 'USE DATABASE', or use a qualified name.
[2024-03-30T01:56:16.210+0000] {taskinstance.py:1149} INFO - Marking task as FAILED. dag_id=migrate_student_data_to_snowflake, task_id=load_data_to_snowflake, execution_date=20240329T000000, start_date=20240330T015614, end_date=20240330T015616
[2024-03-30T01:56:16.220+0000] {standard_task_runner.py:107} ERROR - Failed to execute job 144 for task load_data_to_snowflake (090105 (22000): 01b352ef-0000-3e0f-0000-0000499135e1: Cannot perform CREATE TABLE. This session does not have a current database. Call 'USE DATABASE', or use a qualified name.; 206)
[2024-03-30T01:56:16.232+0000] {local_task_job_runner.py:234} INFO - Task exited with return code 1
[2024-03-30T01:56:16.245+0000] {taskinstance.py:3312} INFO - 0 downstream tasks scheduled from follow-on schedule check
[2024-03-30T02:35:30.442+0000] {taskinstance.py:1979} INFO - Dependencies all met for dep_context=non-requeueable deps ti=<TaskInstance: migrate_student_data_to_snowflake.load_data_to_snowflake scheduled__2024-03-29T00:00:00+00:00 [queued]>
[2024-03-30T02:35:30.452+0000] {taskinstance.py:1979} INFO - Dependencies all met for dep_context=requeueable deps ti=<TaskInstance: migrate_student_data_to_snowflake.load_data_to_snowflake scheduled__2024-03-29T00:00:00+00:00 [queued]>
[2024-03-30T02:35:30.453+0000] {taskinstance.py:2193} INFO - Starting attempt 2 of 2
[2024-03-30T02:35:30.471+0000] {taskinstance.py:2217} INFO - Executing <Task(PythonOperator): load_data_to_snowflake> on 2024-03-29 00:00:00+00:00
[2024-03-30T02:35:30.479+0000] {standard_task_runner.py:60} INFO - Started process 181 to run task
[2024-03-30T02:35:30.482+0000] {standard_task_runner.py:87} INFO - Running: ['***', 'tasks', 'run', 'migrate_student_data_to_snowflake', 'load_data_to_snowflake', 'scheduled__2024-03-29T00:00:00+00:00', '--job-id', '193', '--raw', '--subdir', 'DAGS_FOLDER/student_data_migration.py', '--cfg-path', '/tmp/tmpuehowend']
[2024-03-30T02:35:30.486+0000] {standard_task_runner.py:88} INFO - Job 193: Subtask load_data_to_snowflake
[2024-03-30T02:35:30.537+0000] {task_command.py:423} INFO - Running <TaskInstance: migrate_student_data_to_snowflake.load_data_to_snowflake scheduled__2024-03-29T00:00:00+00:00 [running]> on host c5cf3f729977
[2024-03-30T02:35:30.644+0000] {taskinstance.py:2513} INFO - Exporting env vars: AIRFLOW_CTX_DAG_OWNER='***' AIRFLOW_CTX_DAG_ID='migrate_student_data_to_snowflake' AIRFLOW_CTX_TASK_ID='load_data_to_snowflake' AIRFLOW_CTX_EXECUTION_DATE='2024-03-29T00:00:00+00:00' AIRFLOW_CTX_TRY_NUMBER='2' AIRFLOW_CTX_DAG_RUN_ID='scheduled__2024-03-29T00:00:00+00:00'
[2024-03-30T02:35:30.645+0000] {connection.py:386} INFO - Snowflake Connector for Python Version: 3.7.1, Python Version: 3.8.19, Platform: Linux-5.15.146.1-microsoft-standard-WSL2-x86_64-with-glibc2.34
[2024-03-30T02:35:30.646+0000] {connection.py:1211} INFO - This connection is in OCSP Fail Open Mode. TLS Certificates would be checked for validity and revocation status. Any other Certificate Revocation related exceptions or OCSP Responder failures would be disregarded in favor of connectivity.
[2024-03-30T02:35:31.611+0000] {cursor.py:1032} INFO - query: [CREATE DATABASE IF NOT EXISTS VIEWS_STUDENTS]
[2024-03-30T02:35:31.689+0000] {cursor.py:1045} INFO - query execution done
[2024-03-30T02:35:31.690+0000] {cursor.py:1205} INFO - Number of results in first chunk: 1
[2024-03-30T02:35:31.691+0000] {cursor.py:1032} INFO - query: [USE DATABASE VIEWS_STUDENTS]
[2024-03-30T02:35:31.785+0000] {cursor.py:1045} INFO - query execution done
[2024-03-30T02:35:31.786+0000] {cursor.py:1205} INFO - Number of results in first chunk: 1
[2024-03-30T02:35:31.787+0000] {cursor.py:1032} INFO - query: [CREATE SCHEMA IF NOT EXISTS STUDENTS_SEMANTIC]
[2024-03-30T02:35:31.861+0000] {cursor.py:1045} INFO - query execution done
[2024-03-30T02:35:31.862+0000] {cursor.py:1205} INFO - Number of results in first chunk: 1
[2024-03-30T02:35:31.862+0000] {cursor.py:1032} INFO - query: [USE SCHEMA STUDENTS_SEMANTIC]
[2024-03-30T02:35:31.944+0000] {cursor.py:1045} INFO - query execution done
[2024-03-30T02:35:31.945+0000] {cursor.py:1205} INFO - Number of results in first chunk: 1
[2024-03-30T02:35:31.945+0000] {cursor.py:1032} INFO - query: [CREATE OR REPLACE TABLE FINAL_MERGED ( student_id VARCHAR, name VARCHAR, grades ...]
[2024-03-30T02:35:32.175+0000] {cursor.py:1045} INFO - query execution done
[2024-03-30T02:35:32.176+0000] {cursor.py:1205} INFO - Number of results in first chunk: 1
[2024-03-30T02:35:32.186+0000] {student_data_migration.py:144} ERROR - Error loading data into Snowflake: 252004: 252004: Failed processing pyformat-parameters; 255001: 255001: Binding data in type (dict) is not supported.
[2024-03-30T02:35:32.186+0000] {connection.py:734} INFO - closed
[2024-03-30T02:35:32.221+0000] {connection.py:740} INFO - No async queries seem to be running, deleting session
[2024-03-30T02:35:32.283+0000] {taskinstance.py:2731} ERROR - Task failed with exception
Traceback (most recent call last):
  File "/home/airflow/.local/lib/python3.8/site-packages/snowflake/connector/connection.py", line 1517, in _process_params_pyformat
    ret = tuple(res)
  File "/home/airflow/.local/lib/python3.8/site-packages/snowflake/connector/connection.py", line 1563, in _process_single_param
    return _quote(escape(to_snowflake(param)))
  File "/home/airflow/.local/lib/python3.8/site-packages/snowflake/connector/converter.py", line 481, in to_snowflake
    return getattr(self, f"_{type_name}_to_snowflake")(value)
  File "/home/airflow/.local/lib/python3.8/site-packages/snowflake/connector/converter.py", line 653, in __getattr__
    raise ProgrammingError(
snowflake.connector.errors.ProgrammingError: 255001: 255001: Binding data in type (dict) is not supported.

During handling of the above exception, another exception occurred:

Traceback (most recent call last):
  File "/home/airflow/.local/lib/python3.8/site-packages/airflow/models/taskinstance.py", line 444, in _execute_task
    result = _execute_callable(context=context, **execute_callable_kwargs)
  File "/home/airflow/.local/lib/python3.8/site-packages/airflow/models/taskinstance.py", line 414, in _execute_callable
    return execute_callable(context=context, **execute_callable_kwargs)
  File "/home/airflow/.local/lib/python3.8/site-packages/airflow/operators/python.py", line 200, in execute
    return_value = self.execute_callable()
  File "/home/airflow/.local/lib/python3.8/site-packages/airflow/operators/python.py", line 217, in execute_callable
    return self.python_callable(*self.op_args, **self.op_kwargs)
  File "/opt/airflow/dags/student_data_migration.py", line 139, in load_data_to_snowflake
    cursor.executemany(query, data)
  File "/home/airflow/.local/lib/python3.8/site-packages/snowflake/connector/cursor.py", line 1430, in executemany
    fmt % self._connection._process_params_pyformat(param, self)
  File "/home/airflow/.local/lib/python3.8/site-packages/snowflake/connector/connection.py", line 1521, in _process_params_pyformat
    Error.errorhandler_wrapper(
  File "/home/airflow/.local/lib/python3.8/site-packages/snowflake/connector/errors.py", line 290, in errorhandler_wrapper
    handed_over = Error.hand_to_other_handler(
  File "/home/airflow/.local/lib/python3.8/site-packages/snowflake/connector/errors.py", line 345, in hand_to_other_handler
    cursor.errorhandler(connection, cursor, error_class, error_value)
  File "/home/airflow/.local/lib/python3.8/site-packages/snowflake/connector/errors.py", line 221, in default_errorhandler
    raise error_class(
snowflake.connector.errors.ProgrammingError: 252004: 252004: Failed processing pyformat-parameters; 255001: 255001: Binding data in type (dict) is not supported.
[2024-03-30T02:35:32.291+0000] {taskinstance.py:1149} INFO - Marking task as FAILED. dag_id=migrate_student_data_to_snowflake, task_id=load_data_to_snowflake, execution_date=20240329T000000, start_date=20240330T023530, end_date=20240330T023532
[2024-03-30T02:35:32.310+0000] {standard_task_runner.py:107} ERROR - Failed to execute job 193 for task load_data_to_snowflake (252004: 252004: Failed processing pyformat-parameters; 255001: 255001: Binding data in type (dict) is not supported.; 181)
[2024-03-30T02:35:32.344+0000] {local_task_job_runner.py:234} INFO - Task exited with return code 1
[2024-03-30T02:35:32.360+0000] {taskinstance.py:3312} INFO - 0 downstream tasks scheduled from follow-on schedule check
[2024-03-30T02:57:04.887+0000] {taskinstance.py:1979} INFO - Dependencies all met for dep_context=non-requeueable deps ti=<TaskInstance: migrate_student_data_to_snowflake.load_data_to_snowflake scheduled__2024-03-29T00:00:00+00:00 [queued]>
[2024-03-30T02:57:04.894+0000] {taskinstance.py:1979} INFO - Dependencies all met for dep_context=requeueable deps ti=<TaskInstance: migrate_student_data_to_snowflake.load_data_to_snowflake scheduled__2024-03-29T00:00:00+00:00 [queued]>
[2024-03-30T02:57:04.894+0000] {taskinstance.py:2193} INFO - Starting attempt 2 of 2
[2024-03-30T02:57:04.904+0000] {taskinstance.py:2217} INFO - Executing <Task(PythonOperator): load_data_to_snowflake> on 2024-03-29 00:00:00+00:00
[2024-03-30T02:57:04.909+0000] {standard_task_runner.py:60} INFO - Started process 181 to run task
[2024-03-30T02:57:04.911+0000] {standard_task_runner.py:87} INFO - Running: ['***', 'tasks', 'run', 'migrate_student_data_to_snowflake', 'load_data_to_snowflake', 'scheduled__2024-03-29T00:00:00+00:00', '--job-id', '235', '--raw', '--subdir', 'DAGS_FOLDER/student_data_migration.py', '--cfg-path', '/tmp/tmpd4eu4dh1']
[2024-03-30T02:57:04.913+0000] {standard_task_runner.py:88} INFO - Job 235: Subtask load_data_to_snowflake
[2024-03-30T02:57:04.949+0000] {task_command.py:423} INFO - Running <TaskInstance: migrate_student_data_to_snowflake.load_data_to_snowflake scheduled__2024-03-29T00:00:00+00:00 [running]> on host 38988ffa029d
[2024-03-30T02:57:05.048+0000] {taskinstance.py:2513} INFO - Exporting env vars: AIRFLOW_CTX_DAG_OWNER='***' AIRFLOW_CTX_DAG_ID='migrate_student_data_to_snowflake' AIRFLOW_CTX_TASK_ID='load_data_to_snowflake' AIRFLOW_CTX_EXECUTION_DATE='2024-03-29T00:00:00+00:00' AIRFLOW_CTX_TRY_NUMBER='2' AIRFLOW_CTX_DAG_RUN_ID='scheduled__2024-03-29T00:00:00+00:00'
[2024-03-30T02:57:05.049+0000] {connection.py:386} INFO - Snowflake Connector for Python Version: 3.7.1, Python Version: 3.8.19, Platform: Linux-5.15.146.1-microsoft-standard-WSL2-x86_64-with-glibc2.34
[2024-03-30T02:57:05.050+0000] {connection.py:1211} INFO - This connection is in OCSP Fail Open Mode. TLS Certificates would be checked for validity and revocation status. Any other Certificate Revocation related exceptions or OCSP Responder failures would be disregarded in favor of connectivity.
[2024-03-30T02:57:06.535+0000] {cursor.py:1032} INFO - query: [CREATE DATABASE IF NOT EXISTS VIEWS_STUDENTS]
[2024-03-30T02:57:06.670+0000] {cursor.py:1045} INFO - query execution done
[2024-03-30T02:57:06.671+0000] {cursor.py:1205} INFO - Number of results in first chunk: 1
[2024-03-30T02:57:06.671+0000] {cursor.py:1032} INFO - query: [USE DATABASE VIEWS_STUDENTS]
[2024-03-30T02:57:06.771+0000] {cursor.py:1045} INFO - query execution done
[2024-03-30T02:57:06.772+0000] {cursor.py:1205} INFO - Number of results in first chunk: 1
[2024-03-30T02:57:06.772+0000] {cursor.py:1032} INFO - query: [CREATE SCHEMA IF NOT EXISTS STUDENTS_SEMANTIC]
[2024-03-30T02:57:06.861+0000] {cursor.py:1045} INFO - query execution done
[2024-03-30T02:57:06.861+0000] {cursor.py:1205} INFO - Number of results in first chunk: 1
[2024-03-30T02:57:06.862+0000] {cursor.py:1032} INFO - query: [USE SCHEMA STUDENTS_SEMANTIC]
[2024-03-30T02:57:06.958+0000] {cursor.py:1045} INFO - query execution done
[2024-03-30T02:57:06.959+0000] {cursor.py:1205} INFO - Number of results in first chunk: 1
[2024-03-30T02:57:06.960+0000] {cursor.py:1032} INFO - query: [CREATE OR REPLACE TABLE FINAL_MERGED ( student_id VARCHAR, name VARCHAR, grades ...]
[2024-03-30T02:57:07.309+0000] {cursor.py:1045} INFO - query execution done
[2024-03-30T02:57:07.310+0000] {cursor.py:1205} INFO - Number of results in first chunk: 1
[2024-03-30T02:57:07.311+0000] {student_data_migration.py:148} ERROR - Error loading data into Snowflake: not all arguments converted during string formatting
[2024-03-30T02:57:07.312+0000] {connection.py:734} INFO - closed
[2024-03-30T02:57:07.378+0000] {connection.py:740} INFO - No async queries seem to be running, deleting session
[2024-03-30T02:57:07.434+0000] {taskinstance.py:2731} ERROR - Task failed with exception
Traceback (most recent call last):
  File "/home/airflow/.local/lib/python3.8/site-packages/airflow/models/taskinstance.py", line 444, in _execute_task
    result = _execute_callable(context=context, **execute_callable_kwargs)
  File "/home/airflow/.local/lib/python3.8/site-packages/airflow/models/taskinstance.py", line 414, in _execute_callable
    return execute_callable(context=context, **execute_callable_kwargs)
  File "/home/airflow/.local/lib/python3.8/site-packages/airflow/operators/python.py", line 200, in execute
    return_value = self.execute_callable()
  File "/home/airflow/.local/lib/python3.8/site-packages/airflow/operators/python.py", line 217, in execute_callable
    return self.python_callable(*self.op_args, **self.op_kwargs)
  File "/opt/airflow/dags/student_data_migration.py", line 138, in load_data_to_snowflake
    cursor.execute(query, (
  File "/home/airflow/.local/lib/python3.8/site-packages/snowflake/connector/cursor.py", line 1000, in execute
    query = self._preprocess_pyformat_query(command, params)
  File "/home/airflow/.local/lib/python3.8/site-packages/snowflake/connector/cursor.py", line 832, in _preprocess_pyformat_query
    query = command % processed_params
TypeError: not all arguments converted during string formatting
[2024-03-30T02:57:07.444+0000] {taskinstance.py:1149} INFO - Marking task as FAILED. dag_id=migrate_student_data_to_snowflake, task_id=load_data_to_snowflake, execution_date=20240329T000000, start_date=20240330T025704, end_date=20240330T025707
[2024-03-30T02:57:07.453+0000] {standard_task_runner.py:107} ERROR - Failed to execute job 235 for task load_data_to_snowflake (not all arguments converted during string formatting; 181)
[2024-03-30T02:57:07.498+0000] {local_task_job_runner.py:234} INFO - Task exited with return code 1
[2024-03-30T02:57:07.511+0000] {taskinstance.py:3312} INFO - 0 downstream tasks scheduled from follow-on schedule check
[2024-03-30T03:06:35.717+0000] {taskinstance.py:1979} INFO - Dependencies all met for dep_context=non-requeueable deps ti=<TaskInstance: migrate_student_data_to_snowflake.load_data_to_snowflake scheduled__2024-03-29T00:00:00+00:00 [queued]>
[2024-03-30T03:06:35.725+0000] {taskinstance.py:1979} INFO - Dependencies all met for dep_context=requeueable deps ti=<TaskInstance: migrate_student_data_to_snowflake.load_data_to_snowflake scheduled__2024-03-29T00:00:00+00:00 [queued]>
[2024-03-30T03:06:35.726+0000] {taskinstance.py:2193} INFO - Starting attempt 2 of 2
[2024-03-30T03:06:35.736+0000] {taskinstance.py:2217} INFO - Executing <Task(PythonOperator): load_data_to_snowflake> on 2024-03-29 00:00:00+00:00
[2024-03-30T03:06:35.740+0000] {standard_task_runner.py:60} INFO - Started process 197 to run task
[2024-03-30T03:06:35.743+0000] {standard_task_runner.py:87} INFO - Running: ['***', 'tasks', 'run', 'migrate_student_data_to_snowflake', 'load_data_to_snowflake', 'scheduled__2024-03-29T00:00:00+00:00', '--job-id', '248', '--raw', '--subdir', 'DAGS_FOLDER/student_data_migration.py', '--cfg-path', '/tmp/tmpx48cxol1']
[2024-03-30T03:06:35.745+0000] {standard_task_runner.py:88} INFO - Job 248: Subtask load_data_to_snowflake
[2024-03-30T03:06:35.782+0000] {task_command.py:423} INFO - Running <TaskInstance: migrate_student_data_to_snowflake.load_data_to_snowflake scheduled__2024-03-29T00:00:00+00:00 [running]> on host 683019c18b1b
[2024-03-30T03:06:35.890+0000] {taskinstance.py:2513} INFO - Exporting env vars: AIRFLOW_CTX_DAG_OWNER='***' AIRFLOW_CTX_DAG_ID='migrate_student_data_to_snowflake' AIRFLOW_CTX_TASK_ID='load_data_to_snowflake' AIRFLOW_CTX_EXECUTION_DATE='2024-03-29T00:00:00+00:00' AIRFLOW_CTX_TRY_NUMBER='2' AIRFLOW_CTX_DAG_RUN_ID='scheduled__2024-03-29T00:00:00+00:00'
[2024-03-30T03:06:35.891+0000] {connection.py:386} INFO - Snowflake Connector for Python Version: 3.7.1, Python Version: 3.8.19, Platform: Linux-5.15.146.1-microsoft-standard-WSL2-x86_64-with-glibc2.34
[2024-03-30T03:06:35.892+0000] {connection.py:1211} INFO - This connection is in OCSP Fail Open Mode. TLS Certificates would be checked for validity and revocation status. Any other Certificate Revocation related exceptions or OCSP Responder failures would be disregarded in favor of connectivity.
[2024-03-30T03:06:36.715+0000] {cursor.py:1032} INFO - query: [CREATE DATABASE IF NOT EXISTS VIEWS_STUDENTS]
[2024-03-30T03:06:36.803+0000] {cursor.py:1045} INFO - query execution done
[2024-03-30T03:06:36.804+0000] {cursor.py:1205} INFO - Number of results in first chunk: 1
[2024-03-30T03:06:36.805+0000] {cursor.py:1032} INFO - query: [USE DATABASE VIEWS_STUDENTS]
[2024-03-30T03:06:36.930+0000] {cursor.py:1045} INFO - query execution done
[2024-03-30T03:06:36.931+0000] {cursor.py:1205} INFO - Number of results in first chunk: 1
[2024-03-30T03:06:36.931+0000] {cursor.py:1032} INFO - query: [CREATE SCHEMA IF NOT EXISTS STUDENTS_SEMANTIC]
[2024-03-30T03:06:37.043+0000] {cursor.py:1045} INFO - query execution done
[2024-03-30T03:06:37.044+0000] {cursor.py:1205} INFO - Number of results in first chunk: 1
[2024-03-30T03:06:37.044+0000] {cursor.py:1032} INFO - query: [USE SCHEMA STUDENTS_SEMANTIC]
[2024-03-30T03:06:37.153+0000] {cursor.py:1045} INFO - query execution done
[2024-03-30T03:06:37.154+0000] {cursor.py:1205} INFO - Number of results in first chunk: 1
[2024-03-30T03:06:37.155+0000] {cursor.py:1032} INFO - query: [CREATE OR REPLACE TABLE FINAL_MERGED ( student_id VARCHAR, name VARCHAR, grades ...]
[2024-03-30T03:06:37.454+0000] {cursor.py:1045} INFO - query execution done
[2024-03-30T03:06:37.455+0000] {cursor.py:1205} INFO - Number of results in first chunk: 1
[2024-03-30T03:06:37.456+0000] {student_data_migration.py:148} ERROR - Error loading data into Snowflake: not all arguments converted during string formatting
[2024-03-30T03:06:37.456+0000] {connection.py:734} INFO - closed
[2024-03-30T03:06:37.492+0000] {connection.py:740} INFO - No async queries seem to be running, deleting session
[2024-03-30T03:06:37.561+0000] {taskinstance.py:2731} ERROR - Task failed with exception
Traceback (most recent call last):
  File "/home/airflow/.local/lib/python3.8/site-packages/airflow/models/taskinstance.py", line 444, in _execute_task
    result = _execute_callable(context=context, **execute_callable_kwargs)
  File "/home/airflow/.local/lib/python3.8/site-packages/airflow/models/taskinstance.py", line 414, in _execute_callable
    return execute_callable(context=context, **execute_callable_kwargs)
  File "/home/airflow/.local/lib/python3.8/site-packages/airflow/operators/python.py", line 200, in execute
    return_value = self.execute_callable()
  File "/home/airflow/.local/lib/python3.8/site-packages/airflow/operators/python.py", line 217, in execute_callable
    return self.python_callable(*self.op_args, **self.op_kwargs)
  File "/opt/airflow/dags/student_data_migration.py", line 138, in load_data_to_snowflake
    cursor.execute(query, (
  File "/home/airflow/.local/lib/python3.8/site-packages/snowflake/connector/cursor.py", line 1000, in execute
    query = self._preprocess_pyformat_query(command, params)
  File "/home/airflow/.local/lib/python3.8/site-packages/snowflake/connector/cursor.py", line 832, in _preprocess_pyformat_query
    query = command % processed_params
TypeError: not all arguments converted during string formatting
[2024-03-30T03:06:37.575+0000] {taskinstance.py:1149} INFO - Marking task as FAILED. dag_id=migrate_student_data_to_snowflake, task_id=load_data_to_snowflake, execution_date=20240329T000000, start_date=20240330T030635, end_date=20240330T030637
[2024-03-30T03:06:37.591+0000] {standard_task_runner.py:107} ERROR - Failed to execute job 248 for task load_data_to_snowflake (not all arguments converted during string formatting; 197)
[2024-03-30T03:06:37.604+0000] {local_task_job_runner.py:234} INFO - Task exited with return code 1
[2024-03-30T03:06:37.624+0000] {taskinstance.py:3312} INFO - 0 downstream tasks scheduled from follow-on schedule check
[2024-03-30T03:28:36.114+0000] {taskinstance.py:1979} INFO - Dependencies all met for dep_context=non-requeueable deps ti=<TaskInstance: migrate_student_data_to_snowflake.load_data_to_snowflake scheduled__2024-03-29T00:00:00+00:00 [queued]>
[2024-03-30T03:28:36.122+0000] {taskinstance.py:1979} INFO - Dependencies all met for dep_context=requeueable deps ti=<TaskInstance: migrate_student_data_to_snowflake.load_data_to_snowflake scheduled__2024-03-29T00:00:00+00:00 [queued]>
[2024-03-30T03:28:36.122+0000] {taskinstance.py:2193} INFO - Starting attempt 2 of 2
[2024-03-30T03:28:36.132+0000] {taskinstance.py:2217} INFO - Executing <Task(PythonOperator): load_data_to_snowflake> on 2024-03-29 00:00:00+00:00
[2024-03-30T03:28:36.136+0000] {standard_task_runner.py:60} INFO - Started process 203 to run task
[2024-03-30T03:28:36.139+0000] {standard_task_runner.py:87} INFO - Running: ['***', 'tasks', 'run', 'migrate_student_data_to_snowflake', 'load_data_to_snowflake', 'scheduled__2024-03-29T00:00:00+00:00', '--job-id', '262', '--raw', '--subdir', 'DAGS_FOLDER/student_data_migration.py', '--cfg-path', '/tmp/tmp_nfz21yt']
[2024-03-30T03:28:36.141+0000] {standard_task_runner.py:88} INFO - Job 262: Subtask load_data_to_snowflake
[2024-03-30T03:28:36.181+0000] {task_command.py:423} INFO - Running <TaskInstance: migrate_student_data_to_snowflake.load_data_to_snowflake scheduled__2024-03-29T00:00:00+00:00 [running]> on host 7fb200567cf8
[2024-03-30T03:28:36.284+0000] {taskinstance.py:2513} INFO - Exporting env vars: AIRFLOW_CTX_DAG_OWNER='***' AIRFLOW_CTX_DAG_ID='migrate_student_data_to_snowflake' AIRFLOW_CTX_TASK_ID='load_data_to_snowflake' AIRFLOW_CTX_EXECUTION_DATE='2024-03-29T00:00:00+00:00' AIRFLOW_CTX_TRY_NUMBER='2' AIRFLOW_CTX_DAG_RUN_ID='scheduled__2024-03-29T00:00:00+00:00'
[2024-03-30T03:28:36.286+0000] {connection.py:386} INFO - Snowflake Connector for Python Version: 3.7.1, Python Version: 3.8.19, Platform: Linux-5.15.146.1-microsoft-standard-WSL2-x86_64-with-glibc2.34
[2024-03-30T03:28:36.287+0000] {connection.py:1211} INFO - This connection is in OCSP Fail Open Mode. TLS Certificates would be checked for validity and revocation status. Any other Certificate Revocation related exceptions or OCSP Responder failures would be disregarded in favor of connectivity.
[2024-03-30T03:28:36.568+0000] {cursor.py:1032} INFO - query: [CREATE DATABASE IF NOT EXISTS VIEWS_STUDENTS]
[2024-03-30T03:28:36.652+0000] {cursor.py:1045} INFO - query execution done
[2024-03-30T03:28:36.654+0000] {cursor.py:1205} INFO - Number of results in first chunk: 1
[2024-03-30T03:28:36.655+0000] {cursor.py:1032} INFO - query: [USE DATABASE VIEWS_STUDENTS]
[2024-03-30T03:28:36.756+0000] {cursor.py:1045} INFO - query execution done
[2024-03-30T03:28:36.757+0000] {cursor.py:1205} INFO - Number of results in first chunk: 1
[2024-03-30T03:28:36.757+0000] {cursor.py:1032} INFO - query: [CREATE SCHEMA IF NOT EXISTS STUDENTS_SEMANTIC]
[2024-03-30T03:28:36.819+0000] {cursor.py:1045} INFO - query execution done
[2024-03-30T03:28:36.821+0000] {cursor.py:1205} INFO - Number of results in first chunk: 1
[2024-03-30T03:28:36.822+0000] {cursor.py:1032} INFO - query: [USE SCHEMA STUDENTS_SEMANTIC]
[2024-03-30T03:28:36.917+0000] {cursor.py:1045} INFO - query execution done
[2024-03-30T03:28:36.918+0000] {cursor.py:1205} INFO - Number of results in first chunk: 1
[2024-03-30T03:28:36.919+0000] {cursor.py:1032} INFO - query: [CREATE OR REPLACE TABLE FINAL_MERGED ( student_id VARCHAR, name VARCHAR, grades ...]
[2024-03-30T03:28:37.190+0000] {cursor.py:1045} INFO - query execution done
[2024-03-30T03:28:37.191+0000] {cursor.py:1205} INFO - Number of results in first chunk: 1
[2024-03-30T03:28:37.193+0000] {student_data_migration.py:148} ERROR - Error loading data into Snowflake: not all arguments converted during string formatting
[2024-03-30T03:28:37.194+0000] {connection.py:734} INFO - closed
[2024-03-30T03:28:37.227+0000] {connection.py:740} INFO - No async queries seem to be running, deleting session
[2024-03-30T03:28:37.285+0000] {taskinstance.py:2731} ERROR - Task failed with exception
Traceback (most recent call last):
  File "/home/airflow/.local/lib/python3.8/site-packages/airflow/models/taskinstance.py", line 444, in _execute_task
    result = _execute_callable(context=context, **execute_callable_kwargs)
  File "/home/airflow/.local/lib/python3.8/site-packages/airflow/models/taskinstance.py", line 414, in _execute_callable
    return execute_callable(context=context, **execute_callable_kwargs)
  File "/home/airflow/.local/lib/python3.8/site-packages/airflow/operators/python.py", line 200, in execute
    return_value = self.execute_callable()
  File "/home/airflow/.local/lib/python3.8/site-packages/airflow/operators/python.py", line 217, in execute_callable
    return self.python_callable(*self.op_args, **self.op_kwargs)
  File "/opt/airflow/dags/student_data_migration.py", line 138, in load_data_to_snowflake
    cursor.execute(query, (
  File "/home/airflow/.local/lib/python3.8/site-packages/snowflake/connector/cursor.py", line 1000, in execute
    query = self._preprocess_pyformat_query(command, params)
  File "/home/airflow/.local/lib/python3.8/site-packages/snowflake/connector/cursor.py", line 832, in _preprocess_pyformat_query
    query = command % processed_params
TypeError: not all arguments converted during string formatting
[2024-03-30T03:28:37.298+0000] {taskinstance.py:1149} INFO - Marking task as FAILED. dag_id=migrate_student_data_to_snowflake, task_id=load_data_to_snowflake, execution_date=20240329T000000, start_date=20240330T032836, end_date=20240330T032837
[2024-03-30T03:28:37.307+0000] {standard_task_runner.py:107} ERROR - Failed to execute job 262 for task load_data_to_snowflake (not all arguments converted during string formatting; 203)
[2024-03-30T03:28:37.318+0000] {local_task_job_runner.py:234} INFO - Task exited with return code 1
[2024-03-30T03:28:37.330+0000] {taskinstance.py:3312} INFO - 0 downstream tasks scheduled from follow-on schedule check
